2025-06-23 14:57:32,055 p=84901 u=bill n=ansible INFO| fatal: [dell]: UNREACHABLE! => {"changed": false, "msg": "Data could not be sent to remote host \"192.168.86.55\". Make sure this host can be reached over ssh: ssh: connect to host 192.168.86.55 port 22: No route to host\r\n", "unreachable": true}
2025-06-23 14:57:32,061 p=84901 u=bill n=ansible INFO| fatal: [samsung]: UNREACHABLE! => {"changed": false, "msg": "Data could not be sent to remote host \"192.168.86.94\". Make sure this host can be reached over ssh: ssh: connect to host 192.168.86.94 port 22: No route to host\r\n", "unreachable": true}
2025-06-23 14:57:43,397 p=84901 u=bill n=ansible INFO| fatal: [lily_laptop]: UNREACHABLE! => {"changed": false, "msg": "Data could not be sent to remote host \"192.168.86.53\". Make sure this host can be reached over ssh: ssh: connect to host 192.168.86.53 port 22: Connection timed out\r\n", "unreachable": true}
2025-06-23 14:57:46,344 p=84901 u=bill n=ansible INFO| fatal: [pbs]: FAILED! => {"msg": "Timeout (12s) waiting for privilege escalation prompt: "}
2025-06-23 14:58:49,876 p=84901 u=bill n=ansible INFO| fatal: [sab]: FAILED! => {"msg": "Timeout (12s) waiting for privilege escalation prompt: "}
2025-06-23 14:59:02,039 p=84901 u=bill n=ansible INFO| fatal: [homepage]: FAILED! => {"msg": "Timeout (12s) waiting for privilege escalation prompt: "}
2025-06-23 15:03:18,176 p=84901 u=bill n=ansible INFO| fatal: [desktop]: FAILED! => {"changed": false, "msg": "Failed to update apt cache after 5 retries: "}
2025-06-23 15:03:18,481 p=84901 u=bill n=ansible INFO| fatal: [desktop]: FAILED! => {"changed": false, "module_stderr": "Traceback (most recent call last):\n  File \"<stdin>\", line 107, in <module>\n  File \"<stdin>\", line 99, in _ansiballz_main\n  File \"<stdin>\", line 47, in invoke_module\n  File \"<frozen runpy>\", line 226, in run_module\n  File \"<frozen runpy>\", line 98, in _run_module_code\n  File \"<frozen runpy>\", line 88, in _run_code\n  File \"/tmp/ansible_apt_repository_payload_0958byvu/ansible_apt_repository_payload.zip/ansible/modules/apt_repository.py\", line 782, in <module>\n  File \"/tmp/ansible_apt_repository_payload_0958byvu/ansible_apt_repository_payload.zip/ansible/modules/apt_repository.py\", line 748, in main\n  File \"/usr/lib/python3/dist-packages/apt/cache.py\", line 157, in __init__\n    self.open(progress)\n  File \"/usr/lib/python3/dist-packages/apt/cache.py\", line 214, in open\n    self._cache = apt_pkg.Cache(progress)\n                  ^^^^^^^^^^^^^^^^^^^^^^^\napt_pkg.Error: E:Conflicting values set for option Signed-By regarding source https://packages.microsoft.com/repos/code/ stable: /etc/apt/keyrings/packages.microsoft.gpg != /usr/share/keyrings/microsoft.gpg, E:The list of sources could not be read.\n", "module_stdout": "", "msg": "MODULE FAILURE: No start of json char found\nSee stdout/stderr for the exact error", "rc": 1}
2025-06-23 15:03:18,706 p=84901 u=bill n=ansible INFO| fatal: [desktop]: FAILED! => {"changed": false, "msg": "E:Conflicting values set for option Signed-By regarding source https://packages.microsoft.com/repos/code/ stable: /etc/apt/keyrings/packages.microsoft.gpg != /usr/share/keyrings/microsoft.gpg, E:The list of sources could not be read."}
2025-06-23 15:03:18,938 p=84901 u=bill n=ansible INFO| fatal: [desktop]: FAILED! => {"changed": false, "msg": "E:Conflicting values set for option Signed-By regarding source https://packages.microsoft.com/repos/code/ stable: /etc/apt/keyrings/packages.microsoft.gpg != /usr/share/keyrings/microsoft.gpg, E:The list of sources could not be read."}
